<?xml version="1.0"?>
<robot name="simple_mobile_robot" xmlns:xacro="http://www.ros.org/wiki/xacro">

  <link name="base_footprint">
    <inertial>
      <mass value="0.0001"/>
      <inertia ixx="0.0001" ixy="0.0" ixz="0.0" iyy="0.0001" iyz="0.0" izz="0.0001"/>
    </inertial>
  </link>
  
  <link name="base_link">
    <inertial>
      <origin xyz="-0.10 0 0.0285" rpy="0 0 0"/>
      <mass value="5.0"/>
      <inertia 
        ixx="0.1" ixy="0.0" ixz="0.0"
        iyy="0.1" iyz="0.0"
        izz="0.1"/>
    </inertial>

    <visual>
      <origin xyz="-0.10 0 0.0285"/> 
      <geometry>
        <box size="0.34 0.34 0.117"/>
      </geometry>
      <material name="blue">
        <color rgba="0.1 0.2 0.8 1.0"/>
      </material>
    </visual>

    <collision>
      <origin xyz="-0.10 0 0.0285"/>
      <geometry>
        <box size="0.34 0.34 0.117"/>
      </geometry>
    </collision>
  </link>


  <link name="wheel_left_link">
    <inertial>
      <origin xyz="0 0 0"/>
      <mass value="0.2"/>
      <inertia 
        ixx="0.0005" ixy="0.0" ixz="0.0"
        iyy="0.0005" iyz="0.0"
        izz="0.001"/>
    </inertial>

    <visual>
      <origin xyz="0 0 0" rpy="1.5708 0 0"/>
      <geometry>
        <cylinder radius="0.05" length="0.02"/>
      </geometry>
      <material name="black">
        <color rgba="0.05 0.05 0.05 1.0"/>
      </material>
    </visual>

    <collision>
      <origin xyz="0 0 0" rpy="1.5708 0 0"/>
      <geometry>
        <cylinder radius="0.05" length="0.02"/>
      </geometry>
    </collision>
  </link>

  <link name="caster_link">
    <visual>
      <geometry>
        <sphere radius="0.02"/>
      </geometry>
      <material name="black"/>
    </visual>
    <collision>
      <geometry>
        <sphere radius="0.02"/>
      </geometry>
    </collision>
  </link>

  <link name="wheel_right_link">
    <inertial>
      <origin xyz="0 0 0"/>
      <mass value="0.2"/>
      <inertia 
        ixx="0.0005" ixy="0.0" ixz="0.0"
        iyy="0.0005" iyz="0.0"
        izz="0.001"/>
    </inertial>

    <visual>
      <origin xyz="0 0 0" rpy="1.5708 0 0"/>
      <geometry>
        <cylinder radius="0.05" length="0.02"/>
      </geometry>
      <material name="black"/>
    </visual>

    <collision>
      <origin xyz="0 0 0" rpy="1.5708 0 0"/>
      <geometry>
        <cylinder radius="0.05" length="0.02"/>
      </geometry>
    </collision>
  </link>


  <link name="lidar_link">
    <inertial>
      <origin xyz="0 0 0"/>
      <mass value="0.05"/>
      <inertia 
        ixx="0.0001" ixy="0.0" ixz="0.0"
        iyy="0.0001" iyz="0.0"
        izz="0.0001"/>
    </inertial>

    <visual>
      <origin xyz="0 0 0"/>
      <geometry>
        <box size="0.17 0.17 0.09"/> </geometry>
      <material name="gray">
        <color rgba="0.6 0.6 0.6 1.0"/>
      </material>
    </visual>

    <collision>
      <origin xyz="0 0 0"/>
      <geometry>
        <box size="0.17 0.17 0.09"/>
      </geometry>
    </collision>
  </link>

  <link name="imu_link">
    <visual>
      <geometry>
        <box size="0.02 0.02 0.02"/>
      </geometry>
      <material name="black"/>
    </visual>
  </link>

  <link name="camera_link">
    <visual>
      <origin xyz="0 0 0" rpy="0 0 0"/>
      <geometry>
        <box size="0.03 0.125 0.03"/> 
      </geometry>
      <material name="silver">
        <color rgba="0.7 0.7 0.7 1.0"/>
      </material>
    </visual>

    <collision>
      <origin xyz="0 0 0" rpy="0 0 0"/>
      <geometry>
        <box size="0.03 0.125 0.03"/>
      </geometry>
    </collision>

    <inertial>
      <mass value="0.072"/>
      <inertia ixx="0.0001" ixy="0" ixz="0" iyy="0.0001" iyz="0" izz="0.0001"/>
    </inertial>
  </link>

  <joint name="base_link_joint" type="fixed">
    <parent link="base_footprint"/>
    <child link="base_link"/>
    <origin xyz="0 0 0.05" rpy="0 0 0"/>
  </joint>

  <joint name="caster_joint" type="fixed">
    <parent link="base_link"/>
    <child link="caster_link"/>
    <origin xyz="-0.25 0 -0.03" rpy="0 0 0"/>
  </joint>

  <joint name="left_wheel_joint" type="continuous">
    <parent link="base_link"/>
    <child link="wheel_left_link"/>
    <origin xyz="0 0.19 0" rpy="0 0 0"/> 
    <axis xyz="0 1 0"/>
  </joint>

  <joint name="right_wheel_joint" type="continuous">
    <parent link="base_link"/>
    <child link="wheel_right_link"/>
    <origin xyz="0 -0.19 0" rpy="0 0 0"/>
    <axis xyz="0 1 0"/>
  </joint>

  <joint name="lidar_joint" type="fixed">
    <parent link="base_link"/>
    <child link="lidar_link"/>
    <origin xyz="-0.015 0 0.132" rpy="0 0 0"/>  
  </joint>

  <joint name="imu_joint" type="fixed">
    <parent link="base_link"/>
    <child link="imu_link"/>
    <origin xyz="-0.185 0 0.097" rpy="0 0 0"/>
  </joint>

  <joint name="camera_joint" type="fixed">
    <parent link="base_link"/>
    <child link="camera_link"/>
    <origin xyz="0.03 0.0 0.2" rpy="0 0 0"/>
  </joint>

  <gazebo>
    <plugin
      filename="gz-sim-diff-drive-system"
      name="gz::sim::systems::DiffDrive">

      <left_joint>left_wheel_joint</left_joint>
      <right_joint>right_wheel_joint</right_joint>

      <wheel_separation>0.38</wheel_separation>
      <wheel_radius>0.05</wheel_radius>

      <topic>/cmd_vel</topic>

      <odom_topic>/odom</odom_topic>
      <frame_id>odom</frame_id>
      <child_frame_id>base_footprint</child_frame_id>

      <publish_odom>true</publish_odom>
      <publish_tf>true</publish_tf>

    </plugin>
  </gazebo>

  <gazebo reference="lidar_link">
      <sensor name="lidar_sensor" type="gpu_lidar"> <pose>0 0 0 0 0 0</pose>
        <gz_frame_id>lidar_link</gz_frame_id>
        <topic>lidar</topic> <update_rate>30</update_rate>
        <ray>
          <scan>
            <horizontal>
              <samples>360</samples>
              <resolution>1</resolution>
              <min_angle>-3.1415</min_angle>
              <max_angle>3.1415</max_angle>
            </horizontal>
          </scan>
          <range>
            <min>0.1</min>
            <max>10.0</max>
            <resolution>0.01</resolution>
          </range>
        </ray>
        <always_on>1</always_on>
        <visualize>true</visualize>
      </sensor>
    </gazebo>

  <gazebo reference="camera_link">
    <sensor name="depth_camera" type="rgbd_camera">
      <pose>0 0 0 0 0 0</pose>
      <update_rate>30</update_rate>
      <topic>camera</topic>
      <gz_frame_id>camera_link</gz_frame_id>
      <camera>
        <horizontal_fov>1.518</horizontal_fov>
        <image>
          <width>640</width>
          <height>480</height>
          <format>RGB_INT8</format>
        </image>
        <clip>
          <near>0.1</near>
          <far>10.0</far>
        </clip>
      </camera>
      <always_on>1</always_on>
      <visualize>true</visualize>
    </sensor>
  </gazebo>

  <gazebo>
      <plugin
        filename="gz-sim-sensors-system"
        name="gz::sim::systems::Sensors">
        <render_engine>ogre2</render_engine>
      </plugin>
  </gazebo>

  <gazebo reference="imu_link">
    <sensor name="imu_sensor" type="imu">
      <always_on>1</always_on>
      <update_rate>50</update_rate>
      <visualize>true</visualize>
      <topic>imu</topic>
    </sensor>
  </gazebo>

  <gazebo>
    <plugin filename="gz-sim-imu-system" name="gz::sim::systems::Imu"/>
  </gazebo>

  <gazebo reference="wheel_left_link">
    <mu1>1,0</mu1>
    <mu2>1.0</mu2>
  </gazebo>

  <gazebo reference="wheel_right_link">
    <mu1>1.0</mu1>
    <mu2>1.0</mu2>
  </gazebo>

  <gazebo reference="caster_link">
    <mu1>0.0</mu1>
    <mu2>0.0</mu2>
  </gazebo>

</robot>

